Workbook

Sheet _TotalPredTime_training
B32: Average | C32: Std
A33: SVC | B33: =C126 -> 225.99865 | C33: =D126 -> 11.965023
A34: LR | B34: =C140 -> 223.34253 | C34: =D140 -> 13.437971
A35: RF | B35: =C153 -> 286.53002 | C35: =D153 -> 31.207145
A36: ANN | B36: =C166 -> 260.35771 | C36: =D166 -> 25.2789
A37: CNN1D | B37: =C179 -> 257.69058 | C37: =D179 -> 26.225086
A38: CNN2D | B38: =C192 -> 35.937981 | C38: =D192 -> 8.2274043
C114: Average | D114: Std
A115: SVC | B115: predictions_0 | C115: =AVERAGE(F115:DJI115) -> 230.48094 | D115: =_xlfn.STDEV.S(F115:DJI115) -> 13.52631 | F115: 244.4168 | G115: 231.364 | H115: 214.3194 | I115: 231.5217 | J115: 255.4057 | K115: 251.5591 | L115: 235.2329 | M115: 257.9943 | N115: 242.0833 | O115: 263.6784 | P115: 235.402 | Q115: 246.4535 | R115: 257.9342 | S115: 225.8879 | T115: 282.2989 | U115: 245.5574 | V115: 255.893 | W115: 269.6884 | X115: 241.7252 | Y115: 258.688 | Z115: 243.3404 | AA115: 246.619 | AB115: 264.6182 | AC115: 254.7252 | AD115: 263.9083 | AE115: 257.368 | AF115: 238.6438 | AG115: 251.5901 | AH115: 241.9373 | AI115: 239.5482 | AJ115: 246.6905 | AK115: 248.8888 | AL115: 260.7577 | AM115: 240.1513 | AN115: 242.4472 | AO115: 240.2739 | AP115: 238.7719 | AQ115: 226.3902 | AR115: 231.8152 | AS115: 223.3056 | AT115: 219.9552 | AU115: 223.0477 | AV115: 232.017 | AW115: 222.9598 | AX115: 224.6296 | AY115: 211.1215 | AZ115: 210.7856 | BA115: 229.5416 | BB115: 230.8601 | BC115: 231.4868 | BD115: 235.782 | BE115: 223.396 | BF115: 210.59 | BG115: 242.2509 | BH115: 246.9927 | BI115: 248.1992 | BJ115: 231.5461 | BK115: 236.5217 | BL115: 245.9713 | BM115: 234.8481 | BN115: 250.6845 | BO115: 247.5033 | BP115: 257.6371 | BQ115: 222.6618 | BR115: 259.2849 | BS115: 244.2781 | BT115: 237.3599 | BU115: 218.2369 | BV115: 217.7783 | BW115: 236.0725 | BX115: 234.4893 | BY115: 211.791 | BZ115: 239.1147 | CA115: 224.1397 | CB115: 215.5378 | CC115: 225.2246 | CD115: 218.4189 | CE115: 222.9739 | CF115: 212.7299 | CG115: 220.1988 | CH115: 226.4106 | CI115: 234.8387 | CJ115: 211.391 | CK115: 239.9236 | CL115: 256.9038 | CM115: 281.688 | CN115: 259.2165 | CO115: 267.6339 | CP115: 270.0055 | CQ115: 238.3334 | CR115: 253.5069 | CS115: 250.0819 | CT115: 269.5426 | CU115: 250.892 | CV115: 266.5097 | CW115: 255.4123 | CX115: 285.0947 | CY115: 296.8119 | CZ115: 300.6848 | DA115: 283.0574 | DB115: 239.6783 | DC115: 289.9505 | DD115: 287.4049 | DE115: 263.1614 | DF115: 262.9999 | DG115: 277.4664 | DH115: 263.6911 | DI115: 266.7413 | DJ115: 279.6569 | DK115: 286.8903 | DL115: 263.9305 | DM115: 242.2924 | DN115: 233.6743 | DO115: 265.8764 | DP115: 253.0505 | DQ115: 235.6437 | DR115: 247.3282 | DS115: 275.5308 | DT115: 250.4289 | DU115: 262.4114 | DV115: 242.4089 | DW115: 233.1003 | DX115: 252.8079 | DY115: 252.1836 | DZ115: 250.23 | EA115: 244.8941 | EB115: 215.8994 | EC115: 220.8065 | ED115: 220.4596 | EE115: 226.6042 | EF115: 228.6991 | EG115: 216.72 | EH115: 242.1887 | EI115: 216.8747 | EJ115: 236.5551 | EK115: 233.4905 | EL115: 239.9528 | EM115: 248.7675 | EN115: 228.3905 | EO115: 210.8298 | EP115: 230.2629 | EQ115: 224.8845 | ER115: 230.4046 | ES115: 210.6256 | ET115: 212.808 | EU115: 222.3747 | EV115: 237.3031 | EW115: 240.913 | EX115: 205.6026 | EY115: 241.4961 | EZ115: 238.2683 | FA115: 219.4646 | FB115: 237.4429 | FC115: 226.7176 | FD115: 232.8541 | FE115: 239.9875 | FF115: 221.9348 | FG115: 222.393 | FH115: 220.4514 | FI115: 240.0534 | FJ115: 223.1291 | FK115: 223.8482 | FL115: 236.7242 | FM115: 222.6796 | FN115: 238.1137 | FO115: 226.0783 | FP115: 202.5179 | FQ115: 238.376 | FR115: 222.4001 | FS115: 218.7206 | FT115: 227.2856 | FU115: 214.7309 | FV115: 235.6314 | FW115: 216.6453 | FX115: 207.4953 | FY115: 242.1319 | FZ115: 232.5601 | GA115: 243.6063 | GB115: 218.769 | GC115: 226.3334 | GD115: 218.4495 | GE115: 219.7443 | GF115: 223.0073 | GG115: 228.5354 | GH115: 213.8424 | GI115: 235.2368 | GJ115: 233.4301 | GK115: 220.4296 | GL115: 205.3407 | GM115: 213.9615 | GN115: 211.4473 | GO115: 232.3968 | GP115: 222.2047 | GQ115: 211.8482 | GR115: 247.2204 | GS115: 231.9481 | GT115: 225.8204 | GU115: 228.1969 | GV115: 211.7545 | GW115: 229.3511 | GX115: 233.2895 | GY115: 226.4485 | GZ115: 239.9164 | HA115: 228.6543 | HB115: 234.2944 | HC115: 226.3008 | HD115: 226.6082 | HE115: 240.6999 | HF115: 222.9299 | HG115: 232.4059 | HH115: 219.308 | HI115: 220.4278 | HJ115: 225.7493 | HK115: 234.4298 | HL115: 216.5454 | HM115: 221.2862 | HN115: 231.3082 | HO115: 216.092 | HP115: 217.2256 | HQ115: 225.8557 | HR115: 214.3042 | HS115: 221.8004 | HT115: 222.6034 | HU115: 211.2007 | HV115: 206.2416 | HW115: 237.4108 | HX115: 223.4159 | HY115: 222.3169 | HZ115: 235.0776 | IA115: 226.5052 | IB115: 243.0546 | IC115: 214.0312 | ID115: 211.3761 | IE115: 228.8962 | IF115: 244.8578 | IG115: 234.4864 | IH115: 207.7192 | II115: 227.7769 | IJ115: 240.36 | IK115: 228.9204 | IL115: 224.4333 | IM115: 211.8138 | IN115: 245.6928 | IO115: 224.0324 | IP115: 226.4596 | IQ115: 231.826 | IR115: 222.0856 | IS115: 225.8028 | IT115: 221.5946 | IU115: 220.868 | IV115: 224.963 | IW115: 217.1025 | IX115: 242.5625 | IY115: 220.3345 | IZ115: 226.4183 | JA115: 212.1791 | JB115: 231.4711 | JC115: 230.3202 | JD115: 241.8216 | JE115: 232.9537 | JF115: 211.1552 | JG115: 223.3346 | JH115: 233.831 | JI115: 216.1142 | JJ115: 206.3554 | JK115: 230.9807 | JL115: 221.1013 | JM115: 226.9927 | JN115: 249.9237 | JO115: 211.5269 | JP115: 229.0874 | JQ115: 216.884 | JR115: 210.0698 | JS115: 213.6369 | JT115: 236.4131 | JU115: 214.3066 | JV115: 223.7132 | JW115: 235.4466 | JX115: 212.8076 | JY115: 218.0632 | JZ115: 247.6089 | KA115: 235.5758 | KB115: 215.9903 | KC115: 237.847 | KD115: 214.7642 | KE115: 223.5817 | KF115: 232.0159 | KG115: 225.9975 | KH115: 224.7955 | KI115: 229.0451 | KJ115: 223.7844 | KK115: 219.2885 | KL115: 214.8947 | KM115: 217.8243 | KN115: 224.3001 | KO115: 218.239 | KP115: 234.0038 | KQ115: 217.9484 | KR115: 246.2322 | KS115: 218.4272 | KT115: 235.976 | KU115: 239.0379 | KV115: 231.9858 | KW115: 222.4339 | KX115: 216.3887 | KY115: 227.7591 | KZ115: 236.4337 | LA115: 225.7244 | LB115: 219.2753 | LC115: 222.6222 | LD115: 243.3824 | LE115: 225.9029 | LF115: 221.3021 | LG115: 212.2039 | LH115: 217.227 | LI115: 234.4376 | LJ115: 216.4992 | LK115: 224.9574 | LL115: 254.5126 | LM115: 236.099 | LN115: 231.0423 | LO115: 225.2785 | LP115: 233.1721 | LQ115: 248.7245 | LR115: 221.7445 | LS115: 225.2346 | LT115: 235.393 | LU115: 229.1699 | LV115: 218.0017 | LW115: 219.5164 | LX115: 214.3229 | LY115: 231.2684 | LZ115: 218.2617 | MA115: 233.6267 | MB115: 212.5564 | MC115: 217.7585 | MD115: 214.3392 | ME115: 227.602 | MF115: 232.6796 | MG115: 220.4379 | MH115: 225.4866 | MI115: 234.1545 | MJ115: 217.2907 | MK115: 221.028 | ML115: 225.0666 | MM115: 233.3334 | MN115: 227.918 | MO115: 235.3716 | MP115: 212.8112 | MQ115: 225.8309 | MR115: 225.115 | MS115: 215.0341 | MT115: 225.5354 | MU115: 209.1162 | MV115: 222.9324 | MW115: 228.5787 | MX115: 223.4869 | MY115: 206.0868 | MZ115: 240.7687 | NA115: 223.8978 | NB115: 212.8733 | NC115: 225.9192 | ND115: 204.7484 | NE115: 226.3891 | NF115: 224.6863 | NG115: 228.2117 | NH115: 225.9568 | NI115: 232.1661 | NJ115: 234.7 | NK115: 248.5236 | NL115: 237.2837 | NM115: 245.7472 | NN115: 232.4734 | NO115: 256.6581 | NP115: 231.667 | NQ115: 220.9592 | NR115: 218.5701 | NS115: 237.4262 | NT115: 240.1708 | NU115: 228.6518 | NV115: 219.9887 | NW115: 215.0603 | NX115: 215.7268 | NY115: 229.5494 | NZ115: 220.9869 | OA115: 230.9468 | OB115: 238.1157 | OC115: 215.4009 | OD115: 212.5556 | OE115: 229.6657 | OF115: 214.0387 | OG115: 239.3229 | OH115: 246.8921 | OI115: 232.3365 | OJ115: 248.5424 | OK115: 234.1637 | OL115: 230.0625 | OM115: 213.3224 | ON115: 236.9389 | OO115: 231.9688 | OP115: 227.5951 | OQ115: 251.1073 | OR115: 222.1913 | OS115: 237.5575 | OT115: 229.6268 | OU115: 217.6187 | OV115: 245.1215 | OW115: 230.1194 | OX115: 230.6448 | OY115: 219.2124 | OZ115: 235.4093 | PA115: 222.8376 | PB115: 227.8358 | PC115: 229.2275 | PD115: 235.8792 | PE115: 233.7254 | PF115: 254.3739 | PG115: 238.0551 | PH115: 237.0939 | PI115: 225.9067 | PJ115: 234.5582 | PK115: 239.3303 | PL115: 227.6313 | PM115: 248.1231 | PN115: 237.1539 | PO115: 205.0941 | PP115: 229.8144 | PQ115: 226.8371 | PR115: 216.4813 | PS115: 234.1188 | PT115: 225.6283 | PU115: 211.4378 | PV115: 225.0423 | PW115: 217.0407 | PX115: 227.141 | PY115: 226.0647 | PZ115: 230.0138 | QA115: 218.8426 | QB115: 217.5444 | QC115: 221.529 | QD115: 220.9151 | QE115: 224.0976 | QF115: 219.9029 | QG115: 226.7983 | QH115: 235.5236 | QI115: 225.0301 | QJ115: 220.6478 | QK115: 235.2899 | QL115: 224.3282 | QM115: 236.3112 | QN115: 231.6377 | QO115: 215.325 | QP115: 230.4759 | QQ115: 218.3916 | QR115: 231.9716 | QS115: 217.0704 | QT115: 245.0068 | QU115: 219.7701 | QV115: 222.8737 | QW115: 236.0023 | QX115: 207.3796 | QY115: 224.7208 | QZ115: 230.2741 | RA115: 209.8298 | RB115: 230.3915 | RC115: 241.0021 | RD115: 211.2999 | RE115: 225.4321 | RF115: 218.7383 | RG115: 229.68 | RH115: 232.1879 | RI115: 232.359 | RJ115: 230.3049 | RK115: 235.8641 | RL115: 235.0633 | RM115: 222.8278 | RN115: 221.0421 | RO115: 220.1437 | RP115: 228.201 | RQ115: 217.0926 | RR115: 220.6136 | RS115: 227.1534 | RT115: 231.6546 | RU115: 242.335 | RV115: 211.1221 | RW115: 251.7573 | RX115: 228.9874 | RY115: 237.7642 | RZ115: 256.6551 | SA115: 246.585 | SB115: 240.4883 | SC115: 229.6928 | SD115: 237.4103 | SE115: 240.2006 | SF115: 245.4311 | SG115: 235.2236 | SH115: 242.9511 | SI115: 257.3538 | SJ115: 228.4968 | SK115: 218.7028 | SL115: 214.8081 | SM115: 222.0035 | SN115: 231.3248 | SO115: 231.9805 | SP115: 211.8576 | SQ115: 229.6495 | SR115: 235.904 | SS115: 233.9367 | ST115: 217.6564 | SU115: 216.7876 | SV115: 218.5764 | SW115: 250.8191 | SX115: 222.2686 | SY115: 237.97 | SZ115: 226.5941 | TA115: 219.6007 | TB115: 212.5375 | TC115: 239.9394 | TD115: 233.855 | TE115: 231.5102 | TF115: 238.8869 | TG115: 227.5309 | TH115: 219.0506 | TI115: 260.7743 | TJ115: 271.4203 | TK115: 262.3033 | TL115: 246.7001 | TM115: 243.3893 | TN115: 261.3404 | TO115: 248.0642 | TP115: 268.168 | TQ115: 245.4578 | TR115: 230.3915 | TS115: 264.3735 | TT115: 229.7492 | TU115: 239.1733 | TV115: 222.7956 | TW115: 243.1113 | TX115: 249.3154 | TY115: 225.8263 | TZ115: 231.1863 | UA115: 250.0711 | UB115: 234.0336 | UC115: 250.2196 | UD115: 254.3858 | UE115: 237.1977 | UF115: 232.0295 | UG115: 222.8128 | UH115: 226.0473 | UI115: 244.8541 | UJ115: 249.1395 | UK115: 229.7991 | UL115: 259.4145 | UM115: 248.2948 | UN115: 245.5537 | UO115: 239.5557 | UP115: 235.7775 | UQ115: 238.9454 | UR115: 244.5052 | US115: 247.4989 | UT115: 252.1693 | UU115: 247.0013 | UV115: 268.2292 | UW115: 228.0536 | UX115: 243.328 | UY115: 244.453 | UZ115: 246.6089 | VA115: 235.9779 | VB115: 235.5471 | VC115: 227.7636 | VD115: 249.5307 | VE115: 232.5675 | VF115: 237.3084 | VG115: 256.1836 | VH115: 232.4195 | VI115: 234.3612 | VJ115: 220.5608 | VK115: 225.4936 | VL115: 229.8591 | VM115: 245.1728 | VN115: 224.8587 | VO115: 214.9167 | VP115: 251.6652 | VQ115: 241.9498 | VR115: 255.9404 | VS115: 236.8811 | VT115: 222.1191 | VU115: 226.0377 | VV115: 240.9438 | VW115: 209.2458 | VX115: 238.571 | VY115: 215.614 | VZ115: 228.8708 | WA115: 235.5832 | WB115: 219.3724 | WC115: 233.8842 | WD115: 222.3794 | WE115: 224.1319 | WF115: 211.5629 | WG115: 232.9751 | WH115: 226.3267 | WI115: 247.5746 | WJ115: 245.0567 | WK115: 210.2602 | WL115: 226.4489 | WM115: 221.3643 | WN115: 210.2725 | WO115: 234.7289 | WP115: 226.5926 | WQ115: 228.4562 | WR115: 208.5376 | WS115: 234.9214 | WT115: 220.6457 | WU115: 224.278 | WV115: 241.1429 | WW115: 208.6857 | WX115: 221.2611 | WY115: 229.5074 | WZ115: 235.3987 | XA115: 210.9608 | XB115: 215.5479 | XC115: 245.915 | XD115: 220.4354 | XE115: 216.1036 | XF115: 218.3189 | XG115: 222.5925 | XH115: 236.0999 | XI115: 227.0172 | XJ115: 227.1232 | XK115: 229.3141 | XL115: 234.7661 | XM115: 215.0508 | XN115: 224.2526 | XO115: 233.0924 | XP115: 224.6018 | XQ115: 217.4494 | XR115: 225.3842 | XS115: 232.7165 | XT115: 218.7406 | XU115: 235.9014 | XV115: 229.2904 | XW115: 227.7349 | XX115: 239.0687 | XY115: 230.0393 | XZ115: 227.1813 | YA115: 242.1675 | YB115: 220.7638 | YC115: 227.7349 | YD115: 242.1118 | YE115: 218.5792 | YF115: 217.7404 | YG115: 218.7885 | YH115: 248.5686 | YI115: 243.8073 | YJ115: 226.074 | YK115: 226.02 | YL115: 229.7644 | YM115: 237.3998 | YN115: 208.8213 | YO115: 208.1353 | YP115: 231.0119 | YQ115: 207.6398 | YR115: 233.002 | YS115: 223.7315 | YT115: 215.9981 | YU115: 227.2848 | YV115: 224.0127 | YW115: 212.242 | YX115: 219.1156 | YY115: 224.5696 | YZ115: 237.7837 | ZA115: 224.5239 | ZB115: 231.1848 | ZC115: 219.183 | ZD115: 244.8544 | ZE115: 240.0917 | ZF115: 219.0956 | ZG115: 240.5075 | ZH115: 228.409 | ZI115: 225.9471 | ZJ115: 225.4278 | ZK115: 223.4607 | ZL115: 242.3725 | ZM115: 232.2182 | ZN115: 229.9048 | ZO115: 230.0904 | ZP115: 230.319 | ZQ115: 240.6976 | ZR115: 231.0541 | ZS115: 238.123 | ZT115: 219.799 | ZU115: 257.2076 | ZV115: 227.8221 | ZW115: 219.3669 | ZX115: 223.3442 | ZY115: 214.6322 | ZZ115: 229.1264 | AAA115: 231.7619 | AAB115: 217.2191 | AAC115: 228.5352 | AAD115: 218.3509 | AAE115: 246.5278 | AAF115: 213.3148 | AAG115: 220.8775 | AAH115: 242.938 | AAI115: 228.8397 | AAJ115: 238.7282 | AAK115: 222.1971 | AAL115: 221.3352 | AAM115: 220.3109 | AAN115: 217.6868 | AAO115: 227.6315 | AAP115: 245.0332 | AAQ115: 235.7511 | AAR115: 231.4016 | AAS115: 231.6362 | AAT115: 230.3499 | AAU115: 226.0843 | AAV115: 234.278 | AAW115: 229.1553 | AAX115: 224.9628 | AAY115: 210.1139 | AAZ115: 227.434 | ABA115: 213.3111 | ABB115: 236.4576 | ABC115: 225.6299 | ABD115: 216.4218 | ABE115: 229.0098 | ABF115: 226.5635 | ABG115: 240.5305 | ABH115: 223.38 | ABI115: 217.0093 | ABJ115: 224.1539 | ABK115: 238.7652 | ABL115: 227.4154 | ABM115: 224.6814 | ABN115: 249.3744 | ABO115: 219.251 | ABP115: 227.089 | ABQ115: 229.3796 | ABR115: 238.7222 | ABS115: 209.9924 | ABT115: 234.8071 | ABU115: 210.4001 | ABV115: 235.2081 | ABW115: 238.9833 | ABX115: 239.729 | ABY115: 218.8005 | ABZ115: 218.0774 | ACA115: 229.8769 | ACB115: 229.6457 | ACC115: 239.2692 | ACD115: 222.3008 | ACE115: 225.9622 | ACF115: 209.0198 | ACG115: 213.2774 | ACH115: 225.8554 | ACI115: 209.6656 | ACJ115: 234.5916 | ACK115: 232.8418 | ACL115: 225.113 | ACM115: 214.7655 | ACN115: 239.57 | ACO115: 226.2548 | ACP115: 217.8042 | ACQ115: 220.6725 | ACR115: 224.9874 | ACS115: 240.8076 | ACT115: 224.1965 | ACU115: 218.8018 | ACV115: 220.1537 | ACW115: 239.7352 | ACX115: 216.8172 | ACY115: 221.5437 | ACZ115: 220.1505 | ADA115: 229.7899 | ADB115: 229.3192 | ADC115: 234.9237 | ADD115: 227.1525 | ADE115: 220.6009 | ADF115: 236.0844 | ADG115: 218.9805 | ADH115: 213.914 | ADI115: 220.143 | ADJ115: 235.7579 | ADK115: 317.5013 | ADL115: 237.5385 | ADM115: 251.3374 | ADN115: 227.3942 | ADO115: 240.364 | ADP115: 254.7519 | ADQ115: 235.2551 | ADR115: 248.7912 | ADS115: 253.8798 | ADT115: 255.7993 | ADU115: 246.7441 | ADV115: 249.3348 | ADW115: 226.8851 | ADX115: 253.1731 | ADY115: 250.2271 | ADZ115: 239.378 | AEA115: 259.681 | AEB115: 249.9641 | AEC115: 256.9495 | AED115: 266.4773 | AEE115: 259.0225 | AEF115: 245.3716 | AEG115: 236.8786 | AEH115: 257.4123 | AEI115: 251.2057 | AEJ115: 238.3825 | AEK115: 253.5801 | AEL115: 239.2153 | AEM115: 239.1191 | AEN115: 241.3318 | AEO115: 248.6009 | AEP115: 239.7806 | AEQ115: 243.6432 | AER115: 246.1207 | AES115: 233.8358 | AET115: 239.3774 | AEU115: 240.9808 | AEV115: 229.1592 | AEW115: 230.8263 | AEX115: 234.3204 | AEY115: 241.7237 | AEZ115: 238.2951 | AFA115: 246.4711 | AFB115: 231.9752 | AFC115: 245.7831 | AFD115: 243.9938 | AFE115: 241.7382 | AFF115: 235.6169 | AFG115: 247.4782 | AFH115: 253.452 | AFI115: 230.3639 | AFJ115: 217.6561 | AFK115: 219.8956 | AFL115: 230.7687 | AFM115: 227.2219 | AFN115: 220.5847 | AFO115: 227.844 | AFP115: 213.7109 | AFQ115: 263.3055 | AFR115: 264.4039 | AFS115: 211.2884 | AFT115: 233.5688 | AFU115: 241.3656 | AFV115: 237.1908 | AFW115: 238.4235 | AFX115: 219.9436 | AFY115: 229.4226 | AFZ115: 222.7695 | AGA115: 211.369 | AGB115: 222.5094 | AGC115: 222.6912 | AGD115: 235.693 | AGE115: 236.9205 | AGF115: 221.5965 | AGG115: 234.9082 | AGH115: 238.9543 | AGI115: 226.1861 | AGJ115: 231.1782 | AGK115: 236.2188 | AGL115: 244.7564 | AGM115: 223.9993 | AGN115: 227.8672 | AGO115: 245.6397 | AGP115: 215.8509 | AGQ115: 240.2338 | AGR115: 224.7567 | AGS115: 227.0266 | AGT115: 228.4516 | AGU115: 237.4699 | AGV115: 232.9132 | AGW115: 216.8903 | AGX115: 218.3178 | AGY115: 229.9535 | AGZ115: 229.4797 | AHA115: 221.7407 | AHB115: 222.6295 | AHC115: 243.7652 | AHD115: 224.6183 | AHE115: 232.5521 | AHF115: 230.5706 | AHG115: 224.2647 | AHH115: 230.4625 | AHI115: 257.1272 | AHJ115: 225.9588 | AHK115: 231.0784 | AHL115: 223.1685 | AHM115: 233.4801 | AHN115: 221.6518 | AHO115: 207.602 | AHP115: 221.6032 | AHQ115: 238.5314 | AHR115: 216.2439 | AHS115: 230.4299 | AHT115: 222.9741 | AHU115: 232.8803 | AHV115: 220.9538 | AHW115: 232.8167 | AHX115: 225.5697 | AHY115: 228.8037 | AHZ115: 245.7555 | AIA115: 219.129 | AIB115: 225.9644 | AIC115: 232.1381 | AID115: 220.737 | AIE115: 235.8876 | AIF115: 217.4447 | AIG115: 221.8854 | AIH115: 243.6515 | AII115: 248.0692 | AIJ115: 226.9055 | AIK115: 216.4455 | AIL115: 224.874 | AIM115: 214.9751 | AIN115: 238.0294 | AIO115: 224.6148 | AIP115: 234.325 | AIQ115: 237.5 | AIR115: 235.1402 | AIS115: 220.0577 | AIT115: 216.2497 | AIU115: 232.5541 | AIV115: 233.2965 | AIW115: 233.333 | AIX115: 218.9409 | AIY115: 235.8118 | AIZ115: 232.0763 | AJA115: 228.2467 | AJB115: 217.091 | AJC115: 233.4903 | AJD115: 232.4129 | AJE115: 210.0807 | AJF115: 217.0094 | AJG115: 229.6772 | AJH115: 219.7965 | AJI115: 228.5795 | AJJ115: 231.4248 | AJK115: 224.8161 | AJL115: 238.6191 | AJM115: 218.9403 | AJN115: 230.3929 | AJO115: 224.6011 | AJP115: 208.5876 | AJQ115: 228.6997 | AJR115: 207.8463 | AJS115: 212.406 | AJT115: 226.4039 | AJU115: 224.0586 | AJV115: 209.1917 | AJW115: 232.0156 | AJX115: 216.2696 | AJY115: 214.1175 | AJZ115: 222.4625 | AKA115: 217.2077 | AKB115: 224.599 | AKC115: 246.0237 | AKD115: 220.4831 | AKE115: 227.7127 | AKF115: 226.671 | AKG115: 219.1011 | AKH115: 214.7819 | AKI115: 236.6013 | AKJ115: 215.3941 | AKK115: 225.1021 | AKL115: 204.5598 | AKM115: 232.9405 | AKN115: 234.7961 | AKO115: 216.7857 | AKP115: 237.6299 | AKQ115: 217.4647 | AKR115: 244.7965 | AKS115: 239.3836 | AKT115: 237.3702 | AKU115: 212.5086 | AKV115: 218.8774 | AKW115: 228.8206 | AKX115: 231.1522 | AKY115: 219.6888 | AKZ115: 227.6845 | ALA115: 241.7407 | ALB115: 227.412 | ALC115: 227.6756 | ALD115: 222.5762 | ALE115: 220.1802 | ALF115: 227.009 | ALG115: 250.0239 | ALH115: 249.8163 | ALI115: 232.7343 | ALJ115: 236.106 | ALK115: 255.3026 | ALL115: 259.1301 | ALM115: 243.3117 | ALN115: 259.5096 | ALO115: 256.933 | ALP115: 230.5918 | ALQ115: 232.3354 | ALR115: 251.8825 | ALS115: 242.3098 | ALT115: 256.9578 | ALU115: 227.8282 | ALV115: 268.4802 | ALW115: 241.329 | ALX115: 236.7728 | ALY115: 252.879 | ALZ115: 220.6686 | AMA115: 240.2696 | AMB115: 251.516 | AMC115: 257.9316 | AMD115: 232.3663 | AME115: 216.7955 | AMF115: 222.7316 | AMG115: 209.2985 | AMH115: 237.4253 | AMI115: 238.2856 | AMJ115: 221.9918 | AMK115: 220.4966 | AML115: 218.2129 | AMM115: 230.388 | AMN115: 236.3726 | AMO115: 222.05 | AMP115: 235.2977 | AMQ115: 227.1639 | AMR115: 221.6123 | AMS115: 216.2585 | AMT115: 215.741 | AMU115: 209.4309 | AMV115: 229.5349 | AMW115: 230.7619 | AMX115: 218.9128 | AMY115: 225.718 | AMZ115: 225.1673 | ANA115: 224.0151 | ANB115: 223.1372 | ANC115: 221.2208 | AND115: 232.8742 | ANE115: 219.6977 | ANF115: 245.5937 | ANG115: 214.8958 | ANH115: 220.4193 | ANI115: 231.7038 | ANJ115: 225.6233 | ANK115: 304.4976 | ANL115: 235.3409 | ANM115: 244.2855 | ANN115: 238.2078 | ANO115: 255.4746 | ANP115: 252.6049 | ANQ115: 250.9827 | ANR115: 265.9273 | ANS115: 247.0269 | ANT115: 242.1717 | ANU115: 238.3778 | ANV115: 233.9684 | ANW115: 245.1444 | ANX115: 239.2293 | ANY115: 244.3213 | ANZ115: 247.9925 | AOA115: 244.8807 | AOB115: 244.6358 | AOC115: 236.815 | AOD115: 243.2305 | AOE115: 241.633 | AOF115: 238.732 | AOG115: 247.3439 | AOH115: 239.2914 | AOI115: 234.1463 | AOJ115: 229.4462 | AOK115: 236.4763 | AOL115: 246.6124 | AOM115: 239.9417 | AON115: 236.403 | AOO115: 232.8199 | AOP115: 245.5578 | AOQ115: 247.7317 | AOR115: 240.2351 | AOS115: 242.7559 | AOT115: 255.1966 | AOU115: 246.9825 | AOV115: 245.5024 | AOW115: 237.0401 | AOX115: 234.6431 | AOY115: 239.2476 | AOZ115: 256.0078 | APA115: 250.4334 | APB115: 237.7944 | APC115: 246.7134 | APD115: 231.0308 | APE115: 268.5657 | APF115: 245.2075 | APG115: 245.04 | APH115: 250.5623 | API115: 245.2701 | APJ115: 221.7681 | APK115: 211.0739 | APL115: 224.3836 | APM115: 232.6142 | APN115: 249.8892 | APO115: 234.7709 | APP115: 220.3698 | APQ115: 229.5672 | APR115: 215.7076 | APS115: 226.0105 | APT115: 219.7872 | APU115: 209.6028 | APV115: 235.219 | APW115: 238.3913 | APX115: 229.8818 | APY115: 229.3058 | APZ115: 216.5987 | AQA115: 213.8016 | AQB115: 225.6414 | AQC115: 220.4514 | AQD115: 234.521 | AQE115: 214.3621 | AQF115: 229.918 | AQG115: 226.7089 | AQH115: 225.3585 | AQI115: 223.9955 | AQJ115: 224.1262 | AQK115: 226.7854 | AQL115: 215.0472 | AQM115: 235.167 | AQN115: 217.9511 | AQO115: 242.0412 | AQP115: 226.7529 | AQQ115: 213.0694 | AQR115: 224.1275 | AQS115: 216.8613 | AQT115: 222.7356 | AQU115: 243.1197 | AQV115: 219.958 | AQW115: 239.9954 | AQX115: 221.0228 | AQY115: 217.1393 | AQZ115: 221.2799 | ARA115: 223.7583 | ARB115: 250.488 | ARC115: 262.0735 | ARD115: 254.954 | ARE115: 254.721 | ARF115: 248.523 | ARG115: 252.9493 | ARH115: 248.3373 | ARI115: 244.087 | ARJ115: 262.1589 | ARK115: 254.6258 | ARL115: 251.3674 | ARM115: 253.3165 | ARN115: 270.9505 | ARO115: 245.8965 | ARP115: 265.3439 | ARQ115: 242.0971 | ARR115: 238.7731 | ARS115: 224.1063 | ART115: 228.8356 | ARU115: 236.5202 | ARV115: 229.5347 | ARW115: 232.3659 | ARX115: 230.2194 | ARY115: 232.0928 | ARZ115: 212.8008 | ASA115: 222.522 | ASB115: 216.9381 | ASC115: 214.0107 | ASD115: 245.9016 | ASE115: 234.3032 | ASF115: 237.6441 | ASG115: 225.539 | ASH115: 248.021 | ASI115: 228.6561 | ASJ115: 223.1039 | ASK115: 228.7633 | ASL115: 216.737 | ASM115: 226.6912 | ASN115: 225.8131 | ASO115: 227.045 | ASP115: 231.3079 | ASQ115: 227.9839 | ASR115: 231.8497 | ASS115: 223.6553 | AST115: 226.7791 | ASU115: 229.7894 | ASV115: 223.9546 | ASW115: 256.4452 | ASX115: 233.2 | ASY115: 230.5513 | ASZ115: 217.8244 | ATA115: 229.3734 | ATB115: 223.027 | ATC115: 229.0562 | ATD115: 213.7211 | ATE115: 225.7224 | ATF115: 214.4411 | ATG115: 241.8305 | ATH115: 227.6825 | ATI115: 231.713 | ATJ115: 237.4298 | ATK115: 229.7472 | ATL115: 226.7006 | ATM115: 217.816 | ATN115: 228.4349 | ATO115: 237.991 | ATP115: 223.2675 | ATQ115: 215.8581 | ATR115: 222.5069 | ATS115: 228.9217 | ATT115: 243.9765 | ATU115: 213.1756 | ATV115: 235.7071 | ATW115: 207.357 | ATX115: 224.0956 | ATY115: 242.3735 | ATZ115: 236.4849 | AUA115: 246.6872 | AUB115: 239.3159 | AUC115: 232.548 | AUD115: 226.2414 | AUE115: 218.1685 | AUF115: 229.0179 | AUG115: 211.4354 | AUH115: 218.341 | AUI115: 234.0888 | AUJ115: 237.9519 | AUK115: 216.3183 | AUL115: 231.5911 | AUM115: 232.2474 | AUN115: 236.293 | AUO115: 252.3496 | AUP115: 215.6303 | AUQ115: 225.9481 | AUR115: 244.991 | AUS115: 235.3118 | AUT115: 224.0859 | AUU115: 315.5109 | AUV115: 235.8356 | AUW115: 227.3954 | AUX115: 277.5489 | AUY115: 301.1502 | AUZ115: 270.4233 | AVA115: 257.6326 | AVB115: 281.55 | AVC115: 235.7891 | AVD115: 228.4077 | AVE115: 227.1228 | AVF115: 228.1556 | AVG115: 241.2958 | AVH115: 199.6281 | AVI115: 229.5077 | AVJ115: 231.9297 | AVK115: 239.5074 | AVL115: 236.8381 | AVM115: 245.0206 | AVN115: 210.161 | AVO115: 235.1673 | AVP115: 211.4044 | AVQ115: 221.6196 | AVR115: 227.536 | AVS115: 227.9414 | AVT115: 213.8061 | AVU115: 223.6731 | AVV115: 237.664 | AVW115: 225.8196 | AVX115: 212.7464 | AVY115: 235.7053 | AVZ115: 236.2849 | AWA115: 232.5208 | AWB115: 228.6328 | AWC115: 216.0978 | AWD115: 211.339 | AWE115: 224.2377 | AWF115: 231.1364 | AWG115: 224.2087 | AWH115: 214.1755 | AWI115: 232.1159 | AWJ115: 242.5477 | AWK115: 228.7572 | AWL115: 229.3206 | AWM115: 238.0435 | AWN115: 219.2681 | AWO115: 227.9554 | AWP115: 240.8169 | AWQ115: 242.9835 | AWR115: 231.5193 | AWS115: 217.4773 | AWT115: 238.2246 | AWU115: 236.2352 | AWV115: 231.3009 | AWW115: 221.1151 | AWX115: 203.4245 | AWY115: 211.145 | AWZ115: 217.1662 | AXA115: 233.1159 | AXB115: 226.8054 | AXC115: 224.4422 | AXD115: 222.9935 | AXE115: 242.412 | AXF115: 214.708 | AXG115: 217.461 | AXH115: 230.3563 | AXI115: 310.4156 | AXJ115: 253.4507 | AXK115: 235.5269 | AXL115: 224.0488 | AXM115: 247.0899 | AXN115: 252.8626 | AXO115: 237.025 | AXP115: 239.8393 | AXQ115: 248.8058 | AXR115: 247.6926 | AXS115: 245.3049 | AXT115: 249.2468 | AXU115: 219.4836 | AXV115: 249.6637 | AXW115: 248.4211 | AXX115: 228.5228 | AXY115: 252.5673 | AXZ115: 267.129 | AYA115: 240.2258 | AYB115: 249.3524 | AYC115: 259.2219 | AYD115: 238.2578 | AYE115: 232.9394 | AYF115: 238.3365 | AYG115: 264.7546 | AYH115: 243.1469 | AYI115: 250.685 | AYJ115: 235.1625 | AYK115: 239.0659 | AYL115: 247.2122 | AYM115: 241.8772 | AYN115: 245.1292 | AYO115: 243.5776 | AYP115: 232.7024 | AYQ115: 251.327 | AYR115: 246.1216 | AYS115: 250.2798 | AYT115: 252.7857 | AYU115: 259.0284 | AYV115: 256.3301 | AYW115: 251.6586 | AYX115: 230.7616 | AYY115: 261.426 | AYZ115: 230.2199 | AZA115: 233.5316 | AZB115: 226.4489 | AZC115: 248.6866 | AZD115: 241.7941 | AZE115: 256.3521 | AZF115: 250.7933 | AZG115: 245.1125 | AZH115: 231.1556 | AZI115: 222.987 | AZJ115: 210.1897 | AZK115: 236.3064 | AZL115: 230.8768 | AZM115: 239.3035 | AZN115: 231.5924 | AZO115: 228.9863 | AZP115: 210.2653 | AZQ115: 259.8069 | AZR115: 217.5234 | AZS115: 233.6397 | AZT115: 223.5944 | AZU115: 215.0763 | AZV115: 215.9322 | AZW115: 224.8677 | AZX115: 227.9518 | AZY115: 223.4763 | AZZ115: 230.6623 | BAA115: 213.2207 | BAB115: 224.6608 | BAC115: 231.9629 | BAD115: 226.4505 | BAE115: 223.0036 | BAF115: 227.0867 | BAG115: 228.441 | BAH115: 221.8721 | BAI115: 220.6905 | BAJ115: 220.8123 | BAK115: 221.3655 | BAL115: 233.5781 | BAM115: 221.5831 | BAN115: 214.6137 | BAO115: 240.8049 | BAP115: 216.5682 | BAQ115: 218.6269 | BAR115: 217.5124 | BAS115: 226.9833 | BAT115: 219.5685 | BAU115: 247.2764 | BAV115: 222.8861 | BAW115: 237.1229 | BAX115: 214.478 | BAY115: 229.6194 | BAZ115: 227.1297 | BBA115: 212.7855 | BBB115: 233.6694 | BBC115: 226.969 | BBD115: 228.9825 | BBE115: 242.4092 | BBF115: 218.7975 | BBG115: 235.4048 | BBH115: 214.3982 | BBI115: 232.8926 | BBJ115: 219.7626 | BBK115: 227.4177 | BBL115: 243.1733 | BBM115: 225.7637 | BBN115: 231.1202 | BBO115: 224.0475 | BBP115: 210.379 | BBQ115: 235.7731 | BBR115: 220.9902 | BBS115: 245.0227 | BBT115: 234.0337 | BBU115: 233.4394 | BBV115: 233.2856 | BBW115: 215.7737 | BBX115: 215.7125 | BBY115: 239.1735 | BBZ115: 221.4302 | BCA115: 226.3142 | BCB115: 236.9915 | BCC115: 222.1363 | BCD115: 236.9688 | BCE115: 216.2475 | BCF115: 229.9739 | BCG115: 229.3579 | BCH115: 231.0848 | BCI115: 231.1631 | BCJ115: 250.3333 | BCK115: 228.2476 | BCL115: 224.5553 | BCM115: 239.7175 | BCN115: 207.277 | BCO115: 230.643 | BCP115: 238.4811 | BCQ115: 229.5943 | BCR115: 225.2328 | BCS115: 228.5271 | BCT115: 205.9031 | BCU115: 235.1174 | BCV115: 226.2703 | BCW115: 225.4937 | BCX115: 215.1423 | BCY115: 223.1031 | BCZ115: 213.4549 | BDA115: 212.1855 | BDB115: 214.8039 | BDC115: 215.6022 | BDD115: 222.6635 | BDE115: 225.2028 | BDF115: 212.8928 | BDG115: 224.7172 | BDH115: 235.8923 | BDI115: 222.4105 | BDJ115: 217.5815 | BDK115: 216.428 | BDL115: 208.5403 | BDM115: 229.442 | BDN115: 221.6442 | BDO115: 217.693 | BDP115: 226.4901 | BDQ115: 242.7248 | BDR115: 222.3999 | BDS115: 230.8758 | BDT115: 210.4787 | BDU115: 213.9195 | BDV115: 230.9059 | BDW115: 228.8965 | BDX115: 233.4892 | BDY115: 217.5794 | BDZ115: 221.4963 | BEA115: 226.8404 | BEB115: 237.8064 | BEC115: 214.0075 | BED115: 229.704 | BEE115: 229.7458 | BEF115: 237.2333 | BEG115: 213.202 | BEH115: 210.6522 | BEI115: 226.1479 | BEJ115: 232.6629 | BEK115: 205.4856 | BEL115: 238.6263 | BEM115: 203.4691 | BEN115: 224.6373 | BEO115: 221.59 | BEP115: 210.9482 | BEQ115: 232.0741 | BER115: 223.5936 | BES115: 233.5363 | BET115: 235.2391 | BEU115: 213.2361 | BEV115: 236.6217 | BEW115: 227.6722 | BEX115: 221.3633 | BEY115: 214.2286 | BEZ115: 223.1097 | BFA115: 226.1817 | BFB115: 226.6027 | BFC115: 224.7585 | BFD115: 221.0967 | BFE115: 239.6574 | BFF115: 238.9378 | BFG115: 217.2211 | BFH115: 212.5559 | BFI115: 242.5346 | BFJ115: 209.6451 | BFK115: 236.9699 | BFL115: 216.1708 | BFM115: 204.4155 | BFN115: 232.8418 | BFO115: 228.6107 | BFP115: 252.9237 | BFQ115: 214.3395 | BFR115: 222.1065 | BFS115: 224.8 | BFT115: 218.7438 | BFU115: 222.1867 | BFV115: 225.012 | BFW115: 230.5439 | BFX115: 224.9247 | BFY115: 221.7577 | BFZ115: 219.1118 | BGA115: 234.9597 | BGB115: 230.9437 | BGC115: 240.6028 | BGD115: 231.016 | BGE115: 234.6662 | BGF115: 231.9647 | BGG115: 221.7528 | BGH115: 220.7343 | BGI115: 214.1725 | BGJ115: 228.4722 | BGK115: 222.4316 | BGL115: 217.0082 | BGM115: 224.4558 | BGN115: 221.1929 | BGO115: 242.661 | BGP115: 231.5991 | BGQ115: 213.0246 | BGR115: 227.9364 | BGS115: 235.133 | BGT115: 230.4175 | BGU115: 221.1135 | BGV115: 217.0218 | BGW115: 223.0619 | BGX115: 226.6263 | BGY115: 231.4214 | BGZ115: 217.0766 | BHA115: 213.9621 | BHB115: 234.873 | BHC115: 225.0661 | BHD115: 229.3951 | BHE115: 219.0319 | BHF115: 223.8654 | BHG115: 226.8638 | BHH115: 244.5829 | BHI115: 219.3255 | BHJ115: 214.3014 | BHK115: 224.2257 | BHL115: 307.9901 | BHM115: 244.1816 | BHN115: 234.0862 | BHO115: 251.8959 | BHP115: 258.0626 | BHQ115: 243.8334 | BHR115: 246.6801 | BHS115: 251.0066 | BHT115: 244.2593 | BHU115: 261.7048 | BHV115: 235.4687 | BHW115: 245.9673 | BHX115: 221.9037 | BHY115: 221.9577 | BHZ115: 243.3125 | BIA115: 237.7683 | BIB115: 231.3956 | BIC115: 246.5732 | BID115: 256.0774 | BIE115: 238.2109 | BIF115: 244.088 | BIG115: 254.1748 | BIH115: 247.4297 | BII115: 236.2419 | BIJ115: 263.9124 | BIK115: 230.9906 | BIL115: 247.8794 | BIM115: 238.2596 | BIN115: 235.8031 | BIO115: 254.9534 | BIP115: 254.1796 | BIQ115: 251.3784 | BIR115: 261.8721 | BIS115: 261.8135 | BIT115: 240.0139 | BIU115: 253.7747 | BIV115: 245.9835 | BIW115: 249.6694 | BIX115: 253.39 | BIY115: 241.4418 | BIZ115: 256.4006 | BJA115: 243.613 | BJB115: 244.1623 | BJC115: 254.0909 | BJD115: 252.7008 | BJE115: 249.602 | BJF115: 240.5162 | BJG115: 240.0864 | BJH115: 247.5858 | BJI115: 232.2534 | BJJ115: 249.1318 | BJK115: 215.0059 | BJL115: 247.3885 | BJM115: 231.6906 | BJN115: 244.4136 | BJO115: 235.7739 | BJP115: 257.7663 | BJQ115: 222.9199 | BJR115: 239.3189 | BJS115: 237.867 | BJT115: 226.2096 | BJU115: 233.1408 | BJV115: 223.6681 | BJW115: 238.2769 | BJX115: 220.3119 | BJY115: 205.6403 | BJZ115: 222.2934 | BKA115: 222.7429 | BKB115: 217.4596 | BKC115: 230.1744 | BKD115: 219.6567 | BKE115: 229.7001 | BKF115: 223.7422 | BKG115: 226.3717 | BKH115: 216.7695 | BKI115: 220.9918 | BKJ115: 216.9834 | BKK115: 243.0273 | BKL115: 225.9717 | BKM115: 207.1908 | BKN115: 229.2216 | BKO115: 238.3811 | BKP115: 223.8604 | BKQ115: 228.0067 | BKR115: 219.9975 | BKS115: 236.2051 | BKT115: 231.934 | BKU115: 218.5987 | BKV115: 231.9133 | BKW115: 223.1375 | BKX115: 218.5665 | BKY115: 240.4891 | BKZ115: 232.3537 | BLA115: 220.5232 | BLB115: 235.3314 | BLC115: 222.0089 | BLD115: 227.8715 | BLE115: 224.0608 | BLF115: 238.9952 | BLG115: 235.7061 | BLH115: 214.0988 | BLI115: 240.0621 | BLJ115: 216.5013 | BLK115: 217.8256 | BLL115: 221.8452 | BLM115: 213.3446 | BLN115: 227.3411 | BLO115: 228.7064 | BLP115: 207.6207 | BLQ115: 221.1119 | BLR115: 206.4654 | BLS115: 215.5322 | BLT115: 217.2079 | BLU115: 218.7621 | BLV115: 231.7183 | BLW115: 230.7613 | BLX115: 225.2892 | BLY115: 218.7696 | BLZ115: 240.8101 | BMA115: 244.5714 | BMB115: 214.8884 | BMC115: 227.1721 | BMD115: 231.0875 | BME115: 233.544 | BMF115: 235.1868 | BMG115: 235.0962 | BMH115: 233.4409 | BMI115: 230.3631 | BMJ115: 247.7851 | BMK115: 240.9042 | BML115: 231.7096 | BMM115: 237.6188 | BMN115: 217.0642 | BMO115: 222.334 | BMP115: 236.5693 | BMQ115: 228.4355 | BMR115: 211.3253 | BMS115: 217.0875 | BMT115: 227.4137 | BMU115: 237.0484 | BMV115: 224.3219 | BMW115: 228.9038 | BMX115: 233.1247 | BMY115: 219.7595 | BMZ115: 244.0904 | BNA115: 220.1683 | BNB115: 227.688 | BNC115: 208.7963 | BND115: 218.9785 | BNE115: 218.548 | BNF115: 227.2743 | BNG115: 215.9202 | BNH115: 208.0094 | BNI115: 230.2452 | BNJ115: 207.335 | BNK115: 238.2957 | BNL115: 236.4699 | BNM115: 226.8954 | BNN115: 223.7468 | BNO115: 220.3217 | BNP115: 222.9566 | BNQ115: 241.9195 | BNR115: 223.7726 | BNS115: 212.9793 | BNT115: 233.0664 | BNU115: 213.1847 | BNV115: 219.8241 | BNW115: 228.6139 | BNX115: 235.7472 | BNY115: 220.3534 | BNZ115: 232.6793 | BOA115: 217.6438 | BOB115: 235.7989 | BOC115: 227.3267 | BOD115: 227.1271 | BOE115: 228.768 | BOF115: 210.6073 | BOG115: 218.1434 | BOH115: 211.79 | BOI115: 214.2926 | BOJ115: 240.2245 | BOK115: 231.2732 | BOL115: 234.4829 | BOM115: 213.5938 | BON115: 235.1316 | BOO115: 224.4575 | BOP115: 228.4388 | BOQ115: 243.5225 | BOR115: 234.0645 | BOS115: 237.6273 | BOT115: 223.2695 | BOU115: 236.6474 | BOV115: 220.9338 | BOW115: 231.9854 | BOX115: 232.684 | BOY115: 230.4007 | BOZ115: 225.5887 | BPA115: 235.0756 | BPB115: 225.6578 | BPC115: 203.555 | BPD115: 225.4113 | BPE115: 240.7563 | BPF115: 225.8876 | BPG115: 226.6504 | BPH115: 221.0614 | BPI115: 233.1543 | BPJ115: 225.0058 | BPK115: 228.5388 | BPL115: 242.8775 | BPM115: 212.3723 | BPN115: 244.1751 | BPO115: 225.0046 | BPP115: 244.4894 | BPQ115: 225.2775 | BPR115: 236.3553 | BPS115: 227.021 | BPT115: 225.8149 | BPU115: 226.2926 | BPV115: 233.1702 | BPW115: 214.8178 | BPX115: 232.4664 | BPY115: 220.7742 | BPZ115: 213.0483 | BQA115: 228.6767 | BQB115: 229.4997 | BQC115: 222.5762 | BQD115: 240.3447 | BQE115: 227.7401 | BQF115: 227.4198 | BQG115: 229.893 | BQH115: 219.6546 | BQI115: 209.5635 | BQJ115: 235.7081 | BQK115: 231.8295 | BQL115: 237.5878 | BQM115: 234.2906 | BQN115: 240.5407 | BQO115: 226.2009 | BQP115: 237.719 | BQQ115: 228.115 | BQR115: 223.4577 | BQS115: 221.975 | BQT115: 226.2659 | BQU115: 223.7936 | BQV115: 231.5433 | BQW115: 227.6807 | BQX115: 220.6069 | BQY115: 231.2113 | BQZ115: 221.3766 | BRA115: 235.8358 | BRB115: 228.5297 | BRC115: 237.8043 | BRD115: 220.1547 | BRE115: 236.9231 | BRF115: 213.7095 | BRG115: 226.8433 | BRH115: 228.6401 | BRI115: 218.0343 | BRJ115: 212.4767 | BRK115: 238.907 | BRL115: 223.6242 | BRM115: 232.3655 | BRN115: 225.8745 | BRO115: 240.0962 | BRP115: 240.9979 | BRQ115: 206.2295 | BRR115: 226.2457 | BRS115: 245.8591 | BRT115: 207.894 | BRU115: 227.1435 | BRV115: 237.698 | BRW115: 232.6809 | BRX115: 224.8873 | BRY115: 240.3092 | BRZ115: 220.7152 | BSA115: 226.9899 | BSB115: 233.4535 | BSC115: 225.9649 | BSD115: 222.769 | BSE115: 239.5246 | BSF115: 226.7244 | BSG115: 229.7769 | BSH115: 218.7819 | BSI115: 223.3272 | BSJ115: 209.2837 | BSK115: 226.889 | BSL115: 216.3199 | BSM115: 227.7935 | BSN115: 221.0485 | BSO115: 222.0626 | BSP115: 231.6878 | BSQ115: 227.4951 | BSR115: 240.3223 | BSS115: 234.3343 | BST115: 232.8979 | BSU115: 221.3457 | BSV115: 226.0857 | BSW115: 234.287 | BSX115: 219.0769 | BSY115: 245.6493 | BSZ115: 214.5284 | BTA115: 221.6838 | BTB115: 224.2588 | BTC115: 236.7244 | BTD115: 226.3571 | BTE115: 234.8823 | BTF115: 222.0228 | BTG115: 211.0482 | BTH115: 235.0011 | BTI115: 234.5551 | BTJ115: 231.23 | BTK115: 238.9179 | BTL115: 239.7835 | BTM115: 219.3645 | BTN115: 233.4988 | BTO115: 215.5152 | BTP115: 229.7329 | BTQ115: 234.427 | BTR115: 224.9381 | BTS115: 219.7368 | BTT115: 218.3615 | BTU115: 228.6046 | BTV115: 219.7215 | BTW115: 228.5446 | BTX115: 219.9605 | BTY115: 241.9046 | BTZ115: 232.3219 | BUA115: 224.7205 | BUB115: 245.5435 | BUC115: 221.2379 | BUD115: 215.9979 | BUE115: 228.5186 | BUF115: 221.1077 | BUG115: 224.882 | BUH115: 227.3299 | BUI115: 234.0236 | BUJ115: 207.0899 | BUK115: 225.7487 | BUL115: 225.2202 | BUM115: 226.5569 | BUN115: 239.9604 | BUO115: 234.9932 | BUP115: 250.2136 | BUQ115: 230.7778 | BUR115: 229.5605 | BUS115: 228.5681 | BUT115: 206.873 | BUU115: 236.6814 | BUV115: 225.2516 | BUW115: 219.9335 | BUX115: 220.1981 | BUY115: 222.5511 | BUZ115: 242.8128 | BVA115: 229.9931 | BVB115: 216.4445 | BVC115: 217.2108 | BVD115: 226.1758 | BVE115: 231.4968 | BVF115: 230.0479 | BVG115: 242.2919 | BVH115: 233.7809 | BVI115: 240.6374 | BVJ115: 248.8232 | BVK115: 247.6216 | BVL115: 235.3114 | BVM115: 230.0314 | BVN115: 231.3847 | BVO115: 237.5427 | BVP115: 232.0353 | BVQ115: 242.6735 | BVR115: 241.7576 | BVS115: 234.1192 | BVT115: 216.2788 | BVU115: 229.8603 | BVV115: 215.2283 | BVW115: 222.7348 | BVX115: 217.8629 | BVY115: 222.4814 | BVZ115: 248.4547 | BWA115: 228.9849 | BWB115: 223.4882 | BWC115: 231.5442 | BWD115: 240.1743 | BWE115: 225.2154 | BWF115: 212.5392 | BWG115: 225.4867 | BWH115: 232.0162 | BWI115: 234.0559 | BWJ115: 231.738 | BWK115: 232.7441 | BWL115: 240.9191 | BWM115: 225.4261 | BWN115: 246.92 | BWO115: 235.3765 | BWP115: 230.3602 | BWQ115: 233.4765 | BWR115: 222.1327 | BWS115: 230.7549 | BWT115: 237.1726 | BWU115: 220.9019 | BWV115: 225.8838 | BWW115: 232.5859 | BWX115: 219.1649 | BWY115: 228.7074 | BWZ115: 214.0169 | BXA115: 241.1025 | BXB115: 227.7746 | BXC115: 227.1039 | BXD115: 224.7716 | BXE115: 222.9932 | BXF115: 223.439 | BXG115: 216.2604 | BXH115: 221.3082 | BXI115: 250.1879 | BXJ115: 257.7943 | BXK115: 262.3155 | BXL115: 229.3267 | BXM115: 227.6744 | BXN115: 219.2847 | BXO115: 281.5362 | BXP115: 268.8309 | BXQ115: 247.7621 | BXR115: 243.6662 | BXS115: 245.3606 | BXT115: 234.9011 | BXU115: 223.0592 | BXV115: 212.1728 | BXW115: 223.7852 | BXX115: 235.2792 | BXY115: 215.4614 | BXZ115: 241.5777 | BYA115: 225.9805 | BYB115: 232.4095 | BYC115: 221.9731 | BYD115: 227.9403 | BYE115: 236.9373 | BYF115: 215.6523 | BYG115: 229.8736 | BYH115: 225.3833 | BYI115: 226.4554 | BYJ115: 224.8695 | BYK115: 238.9838 | BYL115: 228.3427 | BYM115: 220.8271 | BYN115: 239.2885 | BYO115: 222.2178 | BYP115: 220.9564 | BYQ115: 212.6509 | BYR115: 243.0713 | BYS115: 227.8296 | BYT115: 223.256 | BYU115: 231.8878 | BYV115: 242.4248 | BYW115: 218.5771 | BYX115: 236.4059 | BYY115: 222.0356 | BYZ115: 225.0093 | BZA115: 204.1438 | BZB115: 217.3493 | BZC115: 222.2021 | BZD115: 229.3845 | BZE115: 232.2833 | BZF115: 226.2065 | BZG115: 224.4025 | BZH115: 224.9077 | BZI115: 232.14 | BZJ115: 213.8381 | BZK115: 227.1644 | BZL115: 245.3088 | BZM115: 228.3905 | BZN115: 228.5758 | BZO115: 221.2361 | BZP115: 225.0053 | BZQ115: 233.6616 | BZR115: 226.4774 | BZS115: 223.7303 | BZT115: 243.4048 | BZU115: 228.3088 | BZV115: 235.0464 | BZW115: 229.959 | BZX115: 214.6008 | BZY115: 244.3797 | BZZ115: 226.4718 | CAA115: 230.4854 | CAB115: 218.958 | CAC115: 240.4545 | CAD115: 237.5399 | CAE115: 226.1923 | CAF115: 272.288 | CAG115: 271.3454 | CAH115: 267.9664 | CAI115: 238.1381 | CAJ115: 224.1094 | CAK115: 214.8756 | CAL115: 226.7228 | CAM115: 224.4073 | CAN115: 237.8219 | CAO115: 222.165 | CAP115: 245.8915 | CAQ115: 227.5352 | CAR115: 213.198 | CAS115: 234.3306 | CAT115: 244.7247 | CAU115: 220.7664 | CAV115: 233.9387 | CAW115: 230.5075 | CAX115: 227.8805 | CAY115: 223.2345 | CAZ115: 224.5701 | CBA115: 220.8439 | CBB115: 228.0397 | CBC115: 240.6921 | CBD115: 234.3754 | CBE115: 226.472 | CBF115: 227.4581 | CBG115: 224.7574 | CBH115: 231.6569 | CBI115: 235.2177 | CBJ115: 231.7386 | CBK115: 241.5529 | CBL115: 245.1005 | CBM115: 216.4995 | CBN115: 248.2023 | CBO115: 221.4614 | CBP115: 225.1744 | CBQ115: 217.3213 | CBR115: 223.8938 | CBS115: 205.4743 | CBT115: 222.0635 | CBU115: 232.0246 | CBV115: 220.9801 | CBW115: 223.4149 | CBX115: 244.5457 | CBY115: 236.8301 | CBZ115: 233.694 | CCA115: 217.0903 | CCB115: 240.5432 | CCC115: 240.8962 | CCD115: 236.9567 | CCE115: 218.8247 | CCF115: 213.4562 | CCG115: 225.7156 | CCH115: 236.6029 | CCI115: 225.9911 | CCJ115: 230.5344 | CCK115: 220.118 | CCL115: 240.409 | CCM115: 225.1337 | CCN115: 233.5871 | CCO115: 228.3998 | CCP115: 229.0021 | CCQ115: 228.3756 | CCR115: 232.4379 | CCS115: 223.7872 | CCT115: 225.2601 | CCU115: 234.1522 | CCV115: 242.2567 | CCW115: 217.6132 | CCX115: 205.4452 | CCY115: 219.595 | CCZ115: 231.8418 | CDA115: 227.7628 | CDB115: 224.7065 | CDC115: 224.8172 | CDD115: 214.8694 | CDE115: 236.7785 | CDF115: 222.8074 | CDG115: 227.7472 | CDH115: 216.9696 | CDI115: 220.043 | CDJ115: 227.6353 | CDK115: 210.3051 | CDL115: 206.3822 | CDM115: 237.7577 | CDN115: 224.3432 | CDO115: 199.6148 | CDP115: 226.028 | CDQ115: 254.285 | CDR115: 226.5744 | CDS115: 222.1705 | CDT115: 226.7868 | CDU115: 234.1608 | CDV115: 222.4026 | CDW115: 219.0355 | CDX115: 236.4241 | CDY115: 212.4286 | CDZ115: 216.2265 | CEA115: 230.6392 | CEB115: 232.0598 | CEC115: 229.5209 | CED115: 222.3619 | CEE115: 232.5906 | CEF115: 224.1988 | CEG115: 222.3361 | CEH115: 221.7881 | CEI115: 219.5593 | CEJ115: 238.4946 | CEK115: 220.7581 | CEL115: 221.0531 | CEM115: 235.7818 | CEN115: 235.1721 | CEO115: 220.923 | CEP115: 215.5501 | CEQ115: 217.1859 | CER115: 235.1013 | CES115: 218.1662 | CET115: 238.3409 | CEU115: 215.2482 | CEV115: 226.1068 | CEW115: 226.706 | CEX115: 208.4696 | CEY115: 231.4186 | CEZ115: 225.7595 | CFA115: 242.5162 | CFB115: 223.0083 | CFC115: 227.4996 | CFD115: 229.7621 | CFE115: 245.8022 | CFF115: 233.2822 | CFG115: 237.1063 | CFH115: 213.1913 | CFI115: 214.8996 | CFJ115: 225.2855 | CFK115: 249.6117 | CFL115: 222.9957 | CFM115: 215.2963 | CFN115: 245.5347 | CFO115: 240.6928 | CFP115: 216.5459 | CFQ115: 221.2835 | CFR115: 227.0792 | CFS115: 238.8474 | CFT115: 240.2722 | CFU115: 234.7366 | CFV115: 240.348 | CFW115: 226.31 | CFX115: 215.4012 | CFY115: 228.1164 | CFZ115: 222.0534 | CGA115: 236.0073 | CGB115: 226.6271 | CGC115: 213.7457 | CGD115: 213.5735 | CGE115: 228.1808 | CGF115: 232.745 | CGG115: 217.7768 | CGH115: 220.6902 | CGI115: 216.847 | CGJ115: 221.3971 | CGK115: 243.1385 | CGL115: 213.2234 | CGM115: 219.511 | CGN115: 234.9741 | CGO115: 228.0873 | CGP115: 218.4553 | CGQ115: 227.7994 | CGR115: 220.3542 | CGS115: 260.5867 | CGT115: 219.6231 | CGU115: 213.1835 | CGV115: 263.7212 | CGW115: 225.2307 | CGX115: 223.1813 | CGY115: 227.4324 | CGZ115: 231.1531 | CHA115: 232.3083 | CHB115: 218.0052 | CHC115: 221.8724 | CHD115: 215.5446 | CHE115: 230.2952 | CHF115: 224.8415 | CHG115: 236.0206 | CHH115: 219.3254 | CHI115: 211.5652 | CHJ115: 235.5605 | CHK115: 241.8949 | CHL115: 231.3314 | CHM115: 232.3817 | CHN115: 244.874 | CHO115: 238.2596 | CHP115: 229.8189 | CHQ115: 231.3978 | CHR115: 239.1925 | CHS115: 229.5577 | CHT115: 226.088 | CHU115: 227.4506 | CHV115: 218.1842 | CHW115: 224.1754 | CHX115: 226.7273 | CHY115: 234.6199 | CHZ115: 219.9104 | CIA115: 256.6991 | CIB115: 204.2298 | CIC115: 217.2767 | CID115: 235.9583 | CIE115: 232.7949 | CIF115: 225.3082 | CIG115: 231.6864 | CIH115: 236.8752 | CII115: 241.8495 | CIJ115: 226.7118 | CIK115: 228.1898 | CIL115: 228.4048 | CIM115: 220.814 | CIN115: 221.7138 | CIO115: 232.4154 | CIP115: 222.2381 | CIQ115: 219.8271 | CIR115: 208.0817 | CIS115: 239.8784 | CIT115: 223.4509 | CIU115: 242.1001 | CIV115: 213.3845 | CIW115: 224.619 | CIX115: 223.1063 | CIY115: 225.6281 | CIZ115: 234.0153 | CJA115: 235.3754 | CJB115: 226.2131 | CJC115: 214.7004 | CJD115: 232.7701 | CJE115: 219.9813 | CJF115: 223.5391 | CJG115: 223.0923 | CJH115: 226.3522 | CJI115: 212.8237 | CJJ115: 220.4594 | CJK115: 232.3697 | CJL115: 231.2978 | CJM115: 209.7563 | CJN115: 228.4994 | CJO115: 235.6083 | CJP115: 223.3233 | CJQ115: 226.8492 | CJR115: 208.6486 | CJS115: 229.5614 | CJT115: 234.2327 | CJU115: 217.219 | CJV115: 224.0272 | CJW115: 227.1869 | CJX115: 226.4078 | CJY115: 229.0894 | CJZ115: 208.9372 | CKA115: 222.0257 | CKB115: 234.2652 | CKC115: 223.6742 | CKD115: 230.4826 | CKE115: 228.9772 | CKF115: 222.1024 | CKG115: 222.0349 | CKH115: 252.529 | CKI115: 278.2561 | CKJ115: 236.6947 | CKK115: 228.1263 | CKL115: 236.4747 | CKM115: 223.3033 | CKN115: 238.5763 | CKO115: 224.0062 | CKP115: 225.2865 | CKQ115: 234.1139 | CKR115: 203.5463 | CKS115: 229.1995 | CKT115: 226.1609 | CKU115: 227.3859 | CKV115: 226.5036 | CKW115: 229.2295 | CKX115: 221.2261 | CKY115: 208.5901 | CKZ115: 218.7758 | CLA115: 224.1613 | CLB115: 227.5831 | CLC115: 246.4972 | CLD115: 213.8344 | CLE115: 231.9983 | CLF115: 225.1923 | CLG115: 213.3005 | CLH115: 219.2672 | CLI115: 219.8866 | CLJ115: 221.8166 | CLK115: 235.1253 | CLL115: 219.49 | CLM115: 222.8062 | CLN115: 227.3565 | CLO115: 223.8186 | CLP115: 223.895 | CLQ115: 211.2613 | CLR115: 235.8394 | CLS115: 217.2893 | CLT115: 228.1653 | CLU115: 245.8714 | CLV115: 241.0403 | CLW115: 243.7016 | CLX115: 213.4071 | CLY115: 236.6468 | CLZ115: 217.7483 | CMA115: 204.9248 | CMB115: 227.9563 | CMC115: 222.6756 | CMD115: 224.0673 | CME115: 235.577 | CMF115: 228.8367 | CMG115: 224.5618 | CMH115: 236.5134 | CMI115: 207.0417 | CMJ115: 230.0369 | CMK115: 225.7405 | CML115: 220.8827 | CMM115: 231.4699 | CMN115: 223.1601 | CMO115: 218.7778 | CMP115: 231.9479 | CMQ115: 230.7401 | CMR115: 208.2584 | CMS115: 212.6754 | CMT115: 209.3809 | CMU115: 213.5212 | CMV115: 224.4974 | CMW115: 221.9939 | CMX115: 211.8844 | CMY115: 211.9501 | CMZ115: 242.7698 | CNA115: 226.1409 | CNB115: 213.4053 | CNC115: 225.5371 | CND115: 227.6146 | CNE115: 227.9486 | CNF115: 209.3162 | CNG115: 210.0834 | CNH115: 234.2259 | CNI115: 242.2358 | CNJ115: 205.8467 | CNK115: 211.5197 | CNL115: 221.6163 | CNM115: 231.7633 | CNN115: 226.7373 | CNO115: 246.5975 | CNP115: 224.73 | CNQ115: 203.4063 | CNR115: 228.7444 | CNS115: 225.6065 | CNT115: 227.1296 | CNU115: 225.5108 | CNV115: 227.6896 | CNW115: 226.6267 | CNX115: 226.1214 | CNY115: 219.1652 | CNZ115: 236.1147 | COA115: 224.9797 | COB115: 259.0489 | COC115: 207.6303 | COD115: 224.5901 | COE115: 226.8473 | COF115: 234.4162 | COG115: 212.3466 | COH115: 219.4383 | COI115: 215.4116 | COJ115: 226.7976 | COK115: 237.3381 | COL115: 239.8466 | COM115: 240.5069 | CON115: 229.089 | COO115: 243.4789 | COP115: 230.1673 | COQ115: 218.3543 | COR115: 256.1733 | COS115: 231.7143 | COT115: 238.0871 | COU115: 237.1441 | COV115: 229.7195 | COW115: 232.894 | COX115: 232.1158 | COY115: 236.898 | COZ115: 252.5389 | CPA115: 226.5866 | CPB115: 224.5101 | CPC115: 218.1725 | CPD115: 217.5289 | CPE115: 254.6463 | CPF115: 238.7248 | CPG115: 218.1491 | CPH115: 228.1042 | CPI115: 243.9454 | CPJ115: 250.6912 | CPK115: 210.7546 | CPL115: 220.4854 | CPM115: 238.5013 | CPN115: 219.6192 | CPO115: 243.5982 | CPP115: 255.0869 | CPQ115: 225.9859 | CPR115: 238.382 | CPS115: 238.4779 | CPT115: 213.6567 | CPU115: 225.6331 | CPV115: 226.648 | CPW115: 237.775 | CPX115: 234.8322 | CPY115: 212.5173 | CPZ115: 228.9946 | CQA115: 232.3625 | CQB115: 210.2595 | CQC115: 220.9151 | CQD115: 239.2666 | CQE115: 236.1206 | CQF115: 211.1192 | CQG115: 236.4774 | CQH115: 220.0324 | CQI115: 224.8227 | CQJ115: 244.3925 | CQK115: 228.3477 | CQL115: 217.4872 | CQM115: 239.5712 | CQN115: 238.1327 | CQO115: 242.3266 | CQP115: 247.3014 | CQQ115: 210.2941 | CQR115: 221.9367 | CQS115: 211.4617 | CQT115: 225.7695 | CQU115: 236.9087 | CQV115: 224.9952 | CQW115: 263.0259 | CQX115: 242.6641 | CQY115: 225.9659 | CQZ115: 220.8692 | CRA115: 221.8493 | CRB115: 217.4801 | CRC115: 219.9329 | CRD115: 212.9609 | CRE115: 237.4654 | CRF115: 236.0397 | CRG115: 224.2307 | CRH115: 223.5495 | CRI115: 224.1677 | CRJ115: 241.4141 | CRK115: 220.1412 | CRL115: 220.9344 | CRM115: 228.342 | CRN115: 241.2848 | CRO115: 237.9913 | CRP115: 231.651 | CRQ115: 216.0799 | CRR115: 220.3333 | CRS115: 224.0849 | CRT115: 215.9787 | CRU115: 221.3346 | CRV115: 223.3326 | CRW115: 219.1638 | CRX115: 251.633 | CRY115: 222.9143 | CRZ115: 233.875 | CSA115: 233.1063 | CSB115: 237.2494 | CSC115: 222.5631 | CSD115: 224.6128 | CSE115: 223.9991 | CSF115: 235.0621 | CSG115: 221.556 | CSH115: 218.5863 | CSI115: 233.0175 | CSJ115: 241.4282 | CSK115: 214.2478 | CSL115: 230.9827 | CSM115: 234.8356 | CSN115: 224.6983 | CSO115: 218.7959 | CSP115: 239.7593 | CSQ115: 230.1251 | CSR115: 252.7303 | CSS115: 242.9408 | CST115: 241.1308 | CSU115: 250.6249 | CSV115: 238.3725 | CSW115: 241.47 | CSX115: 225.7327 | CSY115: 236.4644 | CSZ115: 232.9185 | CTA115: 255.5829 | CTB115: 229.9591 | CTC115: 244.185 | CTD115: 225.7667 | CTE115: 241.0646 | CTF115: 232.0082 | CTG115: 256.1159 | CTH115: 233.7131 | CTI115: 217.7084 | CTJ115: 233.5812 | CTK115: 239.0631 | CTL115: 224.0134 | CTM115: 223.0603 | CTN115: 219.2017 | CTO115: 228.8707 | CTP115: 232.7786 | CTQ115: 236.5788 | CTR115: 219.5464 | CTS115: 222.5976 | CTT115: 247.9365 | CTU115: 245.6418 | CTV115: 247.4358 | CTW115: 254.1768 | CTX115: 232.3025 | CTY115: 231.2076 | CTZ115: 225.5574 | CUA115: 222.5386 | CUB115: 248.7951 | CUC115: 229.6343 | CUD115: 219.286 | CUE115: 239.5712 | CUF115: 251.1173 | CUG115: 221.166 | CUH115: 230.1004 | CUI115: 224.6756 | CUJ115: 226.5717 | CUK115: 228.2114 | CUL115: 221.2728 | CUM115: 210.9183 | CUN115: 223.0523 | CUO115: 223.2285 | CUP115: 241.8939 | CUQ115: 216.5508 | CUR115: 227.7118 | CUS115: 222.7891 | CUT115: 219.3682 | CUU115: 225.02 | CUV115: 244.0448 | CUW115: 212.8489 | CUX115: 271.5521 | CUY115: 225.8417 | CUZ115: 226.8815 | CVA115: 239.7154 | CVB115: 239.868 | CVC115: 216.1183 | CVD115: 215.3577 | CVE115: 211.4878 | CVF115: 231.7578 | CVG115: 220.4611 | CVH115: 217.9427 | CVI115: 235.9601 | CVJ115: 239.3698 | CVK115: 215.3285 | CVL115: 232.9578 | CVM115: 217.555 | CVN115: 253.7162 | CVO115: 225.6704 | CVP115: 241.5117 | CVQ115: 227.9038 | CVR115: 224.2674 | CVS115: 227.6083 | CVT115: 232.317 | CVU115: 240.353 | CVV115: 228.3917 | CVW115: 243.3999 | CVX115: 243.5963 | CVY115: 201.4545 | CVZ115: 241.2128 | CWA115: 226.3515 | CWB115: 222.2911 | CWC115: 225.5771 | CWD115: 235.1805 | CWE115: 224.7441 | CWF115: 228.9707 | CWG115: 216.9027 | CWH115: 225.8094 | CWI115: 232.2067 | CWJ115: 215.7527 | CWK115: 233.9209 | CWL115: 215.5393 | CWM115: 217.6767 | CWN115: 236.6524 | CWO115: 223.2278 | CWP115: 228.1853 | CWQ115: 235.4821 | CWR115: 241.2605 | CWS115: 216.6646 | CWT115: 254.5338 | CWU115: 229.3971 | CWV115: 233.9198 | CWW115: 219.0217 | CWX115: 230.1582 | CWY115: 223.6071 | CWZ115: 229.9417 | CXA115: 227.4779 | CXB115: 239.4936 | CXC115: 225.4909 | CXD115: 228.5491 | CXE115: 227.3503 | CXF115: 222.7085 | CXG115: 243.5423 | CXH115: 230.4888 | CXI115: 229.7076 | CXJ115: 231.7963 | CXK115: 226.9075 | CXL115: 217.0451 | CXM115: 227.5711 | CXN115: 215.7424 | CXO115: 219.7241 | CXP115: 228.8189 | CXQ115: 233.8807 | CXR115: 216.2312 | CXS115: 215.4272 | CXT115: 238.9076 | CXU115: 235.1488 | CXV115: 233.3763 | CXW115: 250.1645 | CXX115: 239.0008 | CXY115: 214.6407 | CXZ115: 223.0672 | CYA115: 234.5859 | CYB115: 223.6949 | CYC115: 221.7378 | CYD115: 222.3837 | CYE115: 217.0068 | CYF115: 235.1369 | CYG115: 219.5818 | CYH115: 237.6681 | CYI115: 234.4791 | CYJ115: 223.4056 | CYK115: 209.5079 | CYL115: 230.1927 | CYM115: 227.5474 | CYN115: 210.183 | CYO115: 241.3379 | CYP115: 237.8473 | CYQ115: 233.4928 | CYR115: 216.4547 | CYS115: 235.3801 | CYT115: 226.1515 | CYU115: 232.0047 | CYV115: 224.9797 | CYW115: 241.2535 | CYX115: 233.9552 | CYY115: 246.8242 | CYZ115: 268.6648 | CZA115: 242.1563 | CZB115: 256.7638 | CZC115: 253.0508 | CZD115: 260.3934 | CZE115: 257.8791 | CZF115: 256.7471 | CZG115: 274.8839 | CZH115: 255.9135 | CZI115: 255.3148 | CZJ115: 251.2457 | CZK115: 257.556 | CZL115: 265.7145 | CZM115: 270.1906 | CZN115: 241.6669 | CZO115: 261.2565 | CZP115: 243.5879 | CZQ115: 282.9138 | CZR115: 259.6021 | CZS115: 222.5756 | CZT115: 216.9152 | CZU115: 224.7604 | CZV115: 219.5808 | CZW115: 235.4067 | CZX115: 223.8051 | CZY115: 234.6859 | CZZ115: 238.8845 | DAA115: 215.4237 | DAB115: 226.6106 | DAC115: 229.2282 | DAD115: 223.2128 | DAE115: 239.0237 | DAF115: 234.443 | DAG115: 230.0648 | DAH115: 214.2682 | DAI115: 246.1626 | DAJ115: 227.5158 | DAK115: 203.1224 | DAL115: 220.0699 | DAM115: 240.3661 | DAN115: 237.3077 | DAO115: 247.8655 | DAP115: 217.7335 | DAQ115: 230.7353 | DAR115: 238.5222 | DAS115: 239.9905 | DAT115: 225.2545 | DAU115: 234.5212 | DAV115: 226.0888 | DAW115: 233.8693 | DAX115: 247.2845 | DAY115: 232.996 | DAZ115: 204.1739 | DBA115: 210.7366 | DBB115: 229.8155 | DBC115: 229.0833 | DBD115: 234.7406 | DBE115: 216.4329 | DBF115: 223.3429 | DBG115: 225.4136 | DBH115: 226.9759 | DBI115: 232.3669 | DBJ115: 236.0508 | DBK115: 205.208 | DBL115: 217.0117 | DBM115: 234.3456 | DBN115: 223.7464 | DBO115: 222.1744 | DBP115: 235.2574 | DBQ115: 226.2078 | DBR115: 230.0457 | DBS115: 224.9353 | DBT115: 235.7372 | DBU115: 204.8021 | DBV115: 225.6301 | DBW115: 234.2636 | DBX115: 238.3138 | DBY115: 224.5011 | DBZ115: 242.6334 | DCA115: 227.9968 | DCB115: 228.5986 | DCC115: 218.0165 | DCD115: 224.7888 | DCE115: 264.3102 | DCF115: 218.6778 | DCG115: 234.5669 | DCH115: 206.2398 | DCI115: 231.2093 | DCJ115: 219.5633 | DCK115: 226.1326 | DCL115: 232.4128 | DCM115: 230.6535 | DCN115: 231.3633 | DCO115: 234.5926 | DCP115: 220.3148 | DCQ115: 228.8454 | DCR115: 253.3607 | DCS115: 223.0114 | DCT115: 239.9334 | DCU115: 212.5711 | DCV115: 254.1627 | DCW115: 229.7011 | DCX115: 251.5136 | DCY115: 223.3486 | DCZ115: 235.889 | DDA115: 212.5557 | DDB115: 243.2116 | DDC115: 226.4224 | DDD115: 218.5038 | DDE115: 287.258 | DDF115: 294.4386 | DDG115: 242.3068 | DDH115: 229.6166 | DDI115: 285.5803 | DDJ115: 233.8759 | DDK115: 236.3234 | DDL115: 224.7876 | DDM115: 230.319 | DDN115: 222.3528 | DDO115: 227.632 | DDP115: 230.0604 | DDQ115: 233.7473 | DDR115: 237.0327 | DDS115: 233.8302 | DDT115: 209.4707 | DDU115: 245.0037 | DDV115: 228.904 | DDW115: 209.8107 | DDX115: 213.7123 | DDY115: 215.0197 | DDZ115: 221.3899 | DEA115: 226.5656 | DEB115: 232.165 | DEC115: 211.657 | DED115: 237.2878 | DEE115: 206.942 | DEF115: 219.8498 | DEG115: 220.1122 | DEH115: 211.5978 | DEI115: 231.3866 | DEJ115: 213.4449 | DEK115: 221.6898 | DEL115: 222.6112 | DEM115: 223.136 | DEN115: 216.6843 | DEO115: 235.2255 | DEP115: 214.7675 | DEQ115: 240.0195 | DER115: 234.347 | DES115: 230.6563 | DET115: 223.5463 | DEU115: 215.1967 | DEV115: 228.6557 | DEW115: 203.247 | DEX115: 225.4007 | DEY115: 213.7685 | DEZ115: 203.3381 | DFA115: 220.983 | DFB115: 232.5391 | DFC115: 208.9837 | DFD115: 233.1614 | DFE115: 226.1112 | DFF115: 244.9938 | DFG115: 222.2529 | DFH115: 222.1359 | DFI115: 234.6909 | DFJ115: 225.143 | DFK115: 221.531 | DFL115: 238.112 | DFM115: 235.0718 | DFN115: 224.7179 | DFO115: 226.6059 | DFP115: 221.3219 | DFQ115: 227.1688 | DFR115: 231.3895 | DFS115: 216.626 | DFT115: 225.8563 | DFU115: 227.1235 | DFV115: 233.8176 | DFW115: 217.8303 | DFX115: 226.082 | DFY115: 225.4402 | DFZ115: 227.0855 | DGA115: 240.4315 | DGB115: 208.6067 | DGC115: 236.0831 | DGD115: 232.3135 | DGE115: 239.2758 | DGF115: 230.359 | DGG115: 213.1534 | DGH115: 231.8594 | DGI115: 228.5892 | DGJ115: 234.3137 | DGK115: 210.879 | DGL115: 230.3189 | DGM115: 219.3024 | DGN115: 231.0822 | DGO115: 222.2364 | DGP115: 231.206 | DGQ115: 219.513 | DGR115: 214.4808 | DGS115: 220.62 | DGT115: 215.3454 | DGU115: 239.9068 | DGV115: 205.5792 | DGW115: 229.902 | DGX115: 212.621 | DGY115: 208.7567 | DGZ115: 213.9711 | DHA115: 224.8925 | DHB115: 230.6198 | DHC115: 222.8208 | DHD115: 226.9295 | DHE115: 241.2026 | DHF115: 232.1886 | DHG115: 241.1064 | DHH115: 243.6477 | DHI115: 222.7474 | DHJ115: 232.0854 | DHK115: 218.1873 | DHL115: 216.8402 | DHM115: 240.5283 | DHN115: 218.0129 | DHO115: 231.2495 | DHP115: 239.9282 | DHQ115: 214.0297 | DHR115: 229.8129 | DHS115: 233.8821 | DHT115: 225.2043 | DHU115: 230.7599 | DHV115: 222.9358 | DHW115: 231.705 | DHX115: 230.1654 | DHY115: 232.2793 | DHZ115: 220.612 | DIA115: 220.6114 | DIB115: 225.5443 | DIC115: 226.0434 | DID115: 226.7682 | DIE115: 224.5225 | DIF115: 221.8751 | DIG115: 227.3847 | DIH115: 219.0462 | DII115: 231.4298 | DIJ115: 224.9294 | DIK115: 220.5117 | DIL115: 223.0886 | DIM115: 238.6747 | DIN115: 223.166 | DIO115: 244.8612 | DIP115: 223.9962 | DIQ115: 235.8761 | DIR115: 215.729 | DIS115: 222.0621 | DIT115: 234.0534 | DIU115: 230.3446 | DIV115: 218.083 | DIW115: 215.2462 | DIX115: 232.0276 | DIY115: 238.3291 | DIZ115: 234.4029 | DJA115: 229.4304 | DJB115: 219.3448 | DJC115: 221.5115 | DJD115: 235.5108 | DJE115: 212.444 | DJF115: 233.3882 | DJG115: 238.1633 | DJH115: 234.4048 | DJI115: 213.0418 | DJJ115: 217.4121 | DJK115: 241.764 | DJL115: 245.2475 | DJM115: 235.7892 | DJN115: 235.4642 | DJO115: 236.8388 | DJP115: 221.4375 | DJQ115: 247.6815 | DJR115: 245.3091 | DJS115: 222.3758 | DJT115: 227.9042 | DJU115: 236.4202 | DJV115: 238.6411 | DJW115: 232.3424 | DJX115: 234.2472 | DJY115: 241.793 | DJZ115: 246.3341 | DKA115: 214.7389 | DKB115: 221.263 | DKC115: 242.8261 | DKD115: 213.2814 | DKE115: 234.0744 | DKF115: 234.5695 | DKG115: 220.4898 | DKH115: 217.9534 | DKI115: 217.0088 | DKJ115: 226.5792 | DKK115: 253.9726 | DKL115: 224.6669 | DKM115: 228.4674 | DKN115: 234.5031 | DKO115: 209.7316 | DKP115: 252.7626 | DKQ115: 236.5031 | DKR115: 233.0108 | DKS115: 252.1068 | DKT115: 221.0605 | DKU115: 230.5489 | DKV115: 221.4665 | DKW115: 226.218 | DKX115: 222.4969 | DKY115: 233.2943
